Workbook

Sheet Resumen
A1: Resultados consolidados — prueba_03
A2: Las métricas y totales se calculan mediante fórmulas internas con rangos explícitos; los datos originales se conservan en las hojas por prueba.
A6: N.º | B6: Archivo original | C6: GPS: filas | D6: GPS: RMC con fix | E6: GPS: velocidades RMC | F6: GPS: media km/h | G6: GPS: máximo km/h | H6: GPS: aceptadas firmware | I6: IMU: muestras | J6: IMU: aceleración muestras | K6: IMU: aceleración media m/s² | L6: IMU: giroscopio muestras | M6: IMU: giro medio rad/s | N6: IMU: cuaterniones | O6: GPS: duración s | P6: IMU: duración s | Q6: Eventos
A7: 1 | B7: prueba_03_ventana_00.xlsx | C7: =IFERROR('ventana_00_GPS'!A4,0) | D7: =IFERROR('ventana_00_GPS'!C4,0) | E7: =IFERROR('ventana_00_GPS'!D4,0) | F7: =IFERROR('ventana_00_GPS'!E4,0) | G7: =IFERROR('ventana_00_GPS'!F4,0) | H7: =IFERROR('ventana_00_GPS'!G4,0) | I7: =IFERROR('ventana_00_IMU'!A4,0) | J7: =IFERROR('ventana_00_IMU'!B4,0) | K7: =IFERROR('ventana_00_IMU'!E4,0) | L7: =IFERROR('ventana_00_IMU'!C4,0) | M7: =IFERROR('ventana_00_IMU'!F4,0) | N7: =IFERROR('ventana_00_IMU'!D4,0) | O7: =IFERROR('ventana_00_GPS'!H4,0) | P7: =IFERROR('ventana_00_IMU'!H4,0) | Q7: =IFERROR('ventana_00_Eventos'!B3,0)
B8: TOTAL / CONSOLIDADO | C8: =SUM(C7:C7) | D8: =SUM(D7:D7) | E8: =SUM(E7:E7) | F8: =IFERROR(SUMPRODUCT(E7:E7,F7:F7)/SUM(E7:E7),"") | G8: =IF(COUNT(G7:G7)=0,"",MAX(G7:G7)) | H8: =SUM(H7:H7) | I8: =SUM(I7:I7) | J8: =SUM(J7:J7) | K8: =IFERROR(SUMPRODUCT(J7:J7,K7:K7)/SUM(J7:J7),"") | L8: =SUM(L7:L7) | M8: =IFERROR(SUMPRODUCT(L7:L7,M7:M7)/SUM(L7:L7),"") | N8: =SUM(N7:N7) | O8: =SUM(O7:O7) | P8: =SUM(P7:P7) | Q8: =SUM(Q7:Q7)

Sheet Fuentes
A1: Archivo de entrada | B1: Estado | C1: Hojas importadas | D1: Nota
A2: prueba_03_ventana_00.xlsx | B2: Importado | C2: ventana_00_GPS, ventana_00_IMU, ventana_00_Eventos | D2: Se copiaron los valores de origen; el archivo original permanece intacto.

Sheet ventana_00_GPS
A1: GPS — prueba_03_ventana_00.xlsx
A3: Registros GPS | B3: Registros RMC | C3: RMC con fix válido | D3: Velocidades RMC válidas | E3: Promedio (km/h) | F3: Máximo (km/h) | G3: Velocidades aceptadas | H3: Duración GPS (s)
A4: =COUNTA($C$11:$C$34) | B4: =COUNTIF($C$11:$C$34,"*RMC") | C4: =COUNTIF(X$11:X$34,1) | D4: =COUNT(Y$11:Y$34) | E4: =IFERROR(AVERAGE(Y$11:Y$34),"") | F4: =IF(COUNT(Y$11:Y$34)=0,"",MAX(Y$11:Y$34)) | G4: =COUNT(Z$11:Z$34) | H4: =IFERROR((MAX($B$11:$B$34)-MIN($B$11:$B$34))/1000000,0)
A10: hora_pc | B10: uptime_esp_us | C10: tipo | D10: checksum_valido | E10: parse_valido | F10: hora_gps_ms | G10: rmc_valido | H10: calidad_fix | I10: desfase_rmc_gga_ms | J10: latitud_deg | K10: longitud_deg | L10: velocidad_nudos | M10: velocidad_kmh | N10: rumbo_deg | O10: satelites | P10: hdop | Q10: edad_rmc_ms | R10: edad_gga_ms | S10: estado_gps | T10: estado_velocidad | U10: velocidad_utilizable | V10: nmea_crudo | W10: linea_serial | X10: RMC_fix_valido | Y10: velocidad_RMC_con_fix_kmh | Z10: velocidad_aceptada_firmware_kmh
A11: 2026-10-18T16:15:50.297-07:00 | B11: 382238689 | C11: GPRMC | D11: 1 | E11: 0 | F11: -1 | G11: 0 | H11: 0 | I11: -1 | O11: 0 | P11: 99.99 | Q11: 4294967295 | R11: 4294967295 | S11: SIN_DATOS | T11: SIN_FILTRO | U11: 0 | V11: $GPRMC,,V,,,,,,,,,,N*53 | W11: I (382503) GPS: GPSDIAG|1|382238689|GPRMC|1|0|-1|0|0|-1|nan|nan|nan|nan|nan|0|99.99|4294967295|4294967295|SIN_DATOS|SIN_FILTRO|0|nan|nan|nan|nan|$GPRMC,,V,,,,,,,,,,N*53 | X11: =IF(AND(OR($C11="GPRMC",$C11="GNRMC"),OR($D11=1,$D11=TRUE),OR($E11=1,$E11=TRUE),OR($G11=1,$G11=TRUE)),1,0) | Y11: =IF(AND(AND(OR($C11="GPRMC",$C11="GNRMC"),OR($D11=1,$D11=TRUE),OR($E11=1,$E11=TRUE),OR($G11=1,$G11=TRUE)),ISNUMBER($M11)),$M11,"") | Z11: =IF(AND(AND(OR($C11="GPRMC",$C11="GNRMC"),OR($D11=1,$D11=TRUE),OR($E11=1,$E11=TRUE),OR($G11=1,$G11=TRUE)),OR($U11=1,$U11=TRUE),ISNUMBER($M11)),$M11,"")
A12: 2026-10-18T16:15:50.313-07:00 | B12: 382244180 | C12: GPVTG | D12: 1 | E12: 0 | F12: -1 | G12: 0 | H12: 0 | I12: -1 | O12: 0 | P12: 99.99 | Q12: 4294967295 | R12: 4294967295 | S12: SIN_DATOS | T12: SIN_FILTRO | U12: 0 | V12: $GPVTG,,,,,,,,,N*30 | W12: I (382513) GPS: GPSDIAG|1|382244180|GPVTG|1|0|-1|0|0|-1|nan|nan|nan|nan|nan|0|99.99|4294967295|4294967295|SIN_DATOS|SIN_FILTRO|0|nan|nan|nan|nan|$GPVTG,,,,,,,,,N*30 | X12: =IF(AND(OR($C12="GPRMC",$C12="GNRMC"),OR($D12=1,$D12=TRUE),OR($E12=1,$E12=TRUE),OR($G12=1,$G12=TRUE)),1,0) | Y12: =IF(AND(AND(OR($C12="GPRMC",$C12="GNRMC"),OR($D12=1,$D12=TRUE),OR($E12=1,$E12=TRUE),OR($G12=1,$G12=TRUE)),ISNUMBER($M12)),$M12,"") | Z12: =IF(AND(AND(OR($C12="GPRMC",$C12="GNRMC"),OR($D12=1,$D12=TRUE),OR($E12=1,$E12=TRUE),OR($G12=1,$G12=TRUE)),OR($U12=1,$U12=TRUE),ISNUMBER($M12)),$M12,"")
A13: 2026-10-18T16:15:50.325-07:00 | B13: 382258806 | C13: GPGGA | D13: 1 | E13: 0 | F13: -1 | G13: 0 | H13: 0 | I13: -1 | O13: 0 | P13: 99.99 | Q13: 4294967295 | R13: 4294967295 | S13: SIN_DATOS | T13: SIN_FILTRO | U13: 0 | V13: $GPGGA,,,,,,0,00,99.99,,,,,,*48 | W13: I (382523) GPS: GPSDIAG|1|382258806|GPGGA|1|0|-1|0|0|-1|nan|nan|nan|nan|nan|0|99.99|4294967295|4294967295|SIN_DATOS|SIN_FILTRO|0|nan|nan|nan|nan|$GPGGA,,,,,,0,00,99.99,,,,,,*48 | X13: =IF(AND(OR($C13="GPRMC",$C13="GNRMC"),OR($D13=1,$D13=TRUE),OR($E13=1,$E13=TRUE),OR($G13=1,$G13=TRUE)),1,0) | Y13: =IF(AND(AND(OR($C13="GPRMC",$C13="GNRMC"),OR($D13=1,$D13=TRUE),OR($E13=1,$E13=TRUE),OR($G13=1,$G13=TRUE)),ISNUMBER($M13)),$M13,"") | Z13: =IF(AND(AND(OR($C13="GPRMC",$C13="GNRMC"),OR($D13=1,$D13=TRUE),OR($E13=1,$E13=TRUE),OR($G13=1,$G13=TRUE)),OR($U13=1,$U13=TRUE),ISNUMBER($M13)),$M13,"")
A14: 2026-10-18T16:15:50.349-07:00 | B14: 382292034 | C14: GPGSA | D14: 1 | E14: 0 | F14: -1 | G14: 0 | H14: 0 | I14: -1 | O14: 0 | P14: 99.99 | Q14: 4294967295 | R14: 4294967295 | S14: SIN_DATOS | T14: SIN_FILTRO | U14: 0 | V14: $GPGSA,A,1,,,,,,,,,,,,,99.99,99.99,99.99*30 | W14: I (382563) GPS: GPSDIAG|1|382292034|GPGSA|1|0|-1|0|0|-1|nan|nan|nan|nan|nan|0|99.99|4294967295|4294967295|SIN_DATOS|SIN_FILTRO|0|nan|nan|nan|nan|$GPGSA,A,1,,,,,,,,,,,,,99.99,99.99,99.99*30 | X14: =IF(AND(OR($C14="GPRMC",$C14="GNRMC"),OR($D14=1,$D14=TRUE),OR($E14=1,$E14=TRUE),OR($G14=1,$G14=TRUE)),1,0) | Y14: =IF(AND(AND(OR($C14="GPRMC",$C14="GNRMC"),OR($D14=1,$D14=TRUE),OR($E14=1,$E14=TRUE),OR($G14=1,$G14=TRUE)),ISNUMBER($M14)),$M14,"") | Z14: =IF(AND(AND(OR($C14="GPRMC",$C14="GNRMC"),OR($D14=1,$D14=TRUE),OR($E14=1,$E14=TRUE),OR($G14=1,$G14=TRUE)),OR($U14=1,$U14=TRUE),ISNUMBER($M14)),$M14,"")
A15: 2026-10-18T16:15:50.366-07:00 | B15: 382298170 | C15: GPGSV | D15: 1 | E15: 0 | F15: -1 | G15: 0 | H15: 0 | I15: -1 | O15: 0 | P15: 99.99 | Q15: 4294967295 | R15: 4294967295 | S15: SIN_DATOS | T15: SIN_FILTRO | U15: 0 | V15: $GPGSV,1,1,00*79 | W15: I (382563) GPS: GPSDIAG|1|382298170|GPGSV|1|0|-1|0|0|-1|nan|nan|nan|nan|nan|0|99.99|4294967295|4294967295|SIN_DATOS|SIN_FILTRO|0|nan|nan|nan|nan|$GPGSV,1,1,00*79 | X15: =IF(AND(OR($C15="GPRMC",$C15="GNRMC"),OR($D15=1,$D15=TRUE),OR($E15=1,$E15=TRUE),OR($G15=1,$G15=TRUE)),1,0) | Y15: =IF(AND(AND(OR($C15="GPRMC",$C15="GNRMC"),OR($D15=1,$D15=TRUE),OR($E15=1,$E15=TRUE),OR($G15=1,$G15=TRUE)),ISNUMBER($M15)),$M15,"") | Z15: =IF(AND(AND(OR($C15="GPRMC",$C15="GNRMC"),OR($D15=1,$D15=TRUE),OR($E15=1,$E15=TRUE),OR($G15=1,$G15=TRUE)),OR($U15=1,$U15=TRUE),ISNUMBER($M15)),$M15,"")
A16: 2026-10-18T16:15:50.382-07:00 | B16: 382312348 | C16: GPGLL | D16: 1 | E16: 0 | F16: -1 | G16: 0 | H16: 0 | I16: -1 | O16: 0 | P16: 99.99 | Q16: 4294967295 | R16: 4294967295 | S16: SIN_DATOS | T16: SIN_FILTRO | U16: 0 | V16: $GPGLL,,,,,,V,N*64 | W16: I (382583) GPS: GPSDIAG|1|382312348|GPGLL|1|0|-1|0|0|-1|nan|nan|nan|nan|nan|0|99.99|4294967295|4294967295|SIN_DATOS|SIN_FILTRO|0|nan|nan|nan|nan|$GPGLL,,,,,,V,N*64 | X16: =IF(AND(OR($C16="GPRMC",$C16="GNRMC"),OR($D16=1,$D16=TRUE),OR($E16=1,$E16=TRUE),OR($G16=1,$G16=TRUE)),1,0) | Y16: =IF(AND(AND(OR($C16="GPRMC",$C16="GNRMC"),OR($D16=1,$D16=TRUE),OR($E16=1,$E16=TRUE),OR($G16=1,$G16=TRUE)),ISNUMBER($M16)),$M16,"") | Z16: =IF(AND(AND(OR($C16="GPRMC",$C16="GNRMC"),OR($D16=1,$D16=TRUE),OR($E16=1,$E16=TRUE),OR($G16=1,$G16=TRUE)),OR($U16=1,$U16=TRUE),ISNUMBER($M16)),$M16,"")
A17: 2026-10-18T16:15:51.297-07:00 | B17: 383238647 | C17: GPRMC | D17: 1 | E17: 0 | F17: -1 | G17: 0 | H17: 0 | I17: -1 | O17: 0 | P17: 99.99 | Q17: 4294967295 | R17: 4294967295 | S17: SIN_DATOS | T17: SIN_FILTRO | U17: 0 | V17: $GPRMC,,V,,,,,,,,,,N*53 | W17: I (383503) GPS: GPSDIAG|1|383238647|GPRMC|1|0|-1|0|0|-1|nan|nan|nan|nan|nan|0|99.99|4294967295|4294967295|SIN_DATOS|SIN_FILTRO|0|nan|nan|nan|nan|$GPRMC,,V,,,,,,,,,,N*53 | X17: =IF(AND(OR($C17="GPRMC",$C17="GNRMC"),OR($D17=1,$D17=TRUE),OR($E17=1,$E17=TRUE),OR($G17=1,$G17=TRUE)),1,0) | Y17: =IF(AND(AND(OR($C17="GPRMC",$C17="GNRMC"),OR($D17=1,$D17=TRUE),OR($E17=1,$E17=TRUE),OR($G17=1,$G17=TRUE)),ISNUMBER($M17)),$M17,"") | Z17: =IF(AND(AND(OR($C17="GPRMC",$C17="GNRMC"),OR($D17=1,$D17=TRUE),OR($E17=1,$E17=TRUE),OR($G17=1,$G17=TRUE)),OR($U17=1,$U17=TRUE),ISNUMBER($M17)),$M17,"")
A18: 2026-10-18T16:15:51.313-07:00 | B18: 383244103 | C18: GPVTG | D18: 1 | E18: 0 | F18: -1 | G18: 0 | H18: 0 | I18: -1 | O18: 0 | P18: 99.99 | Q18: 4294967295 | R18: 4294967295 | S18: SIN_DATOS | T18: SIN_FILTRO | U18: 0 | V18: $GPVTG,,,,,,,,,N*30 | W18: I (383513) GPS: GPSDIAG|1|383244103|GPVTG|1|0|-1|0|0|-1|nan|nan|nan|nan|nan|0|99.99|4294967295|4294967295|SIN_DATOS|SIN_FILTRO|0|nan|nan|nan|nan|$GPVTG,,,,,,,,,N*30 | X18: =IF(AND(OR($C18="GPRMC",$C18="GNRMC"),OR($D18=1,$D18=TRUE),OR($E18=1,$E18=TRUE),OR($G18=1,$G18=TRUE)),1,0) | Y18: =IF(AND(AND(OR($C18="GPRMC",$C18="GNRMC"),OR($D18=1,$D18=TRUE),OR($E18=1,$E18=TRUE),OR($G18=1,$G18=TRUE)),ISNUMBER($M18)),$M18,"") | Z18: =IF(AND(AND(OR($C18="GPRMC",$C18="GNRMC"),OR($D18=1,$D18=TRUE),OR($E18=1,$E18=TRUE),OR($G18=1,$G18=TRUE)),OR($U18=1,$U18=TRUE),ISNUMBER($M18)),$M18,"")
A19: 2026-10-18T16:15:51.325-07:00 | B19: 383258729 | C19: GPGGA | D19: 1 | E19: 0 | F19: -1 | G19: 0 | H19: 0 | I19: -1 | O19: 0 | P19: 99.99 | Q19: 4294967295 | R19: 4294967295 | S19: SIN_DATOS | T19: SIN_FILTRO | U19: 0 | V19: $GPGGA,,,,,,0,00,99.99,,,,,,*48 | W19: I (383523) GPS: GPSDIAG|1|383258729|GPGGA|1|0|-1|0|0|-1|nan|nan|nan|nan|nan|0|99.99|4294967295|4294967295|SIN_DATOS|SIN_FILTRO|0|nan|nan|nan|nan|$GPGGA,,,,,,0,00,99.99,,,,,,*48 | X19: =IF(AND(OR($C19="GPRMC",$C19="GNRMC"),OR($D19=1,$D19=TRUE),OR($E19=1,$E19=TRUE),OR($G19=1,$G19=TRUE)),1,0) | Y19: =IF(AND(AND(OR($C19="GPRMC",$C19="GNRMC"),OR($D19=1,$D19=TRUE),OR($E19=1,$E19=TRUE),OR($G19=1,$G19=TRUE)),ISNUMBER($M19)),$M19,"") | Z19: =IF(AND(AND(OR($C19="GPRMC",$C19="GNRMC"),OR($D19=1,$D19=TRUE),OR($E19=1,$E19=TRUE),OR($G19=1,$G19=TRUE)),OR($U19=1,$U19=TRUE),ISNUMBER($M19)),$M19,"")
A20: 2026-10-18T16:15:51.349-07:00 | B20: 383291994 | C20: GPGSA | D20: 1 | E20: 0 | F20: -1 | G20: 0 | H20: 0 | I20: -1 | O20: 0 | P20: 99.99 | Q20: 4294967295 | R20: 4294967295 | S20: SIN_DATOS | T20: SIN_FILTRO | U20: 0 | V20: $GPGSA,A,1,,,,,,,,,,,,,99.99,99.99,99.99*30 | W20: I (383563) GPS: GPSDIAG|1|383291994|GPGSA|1|0|-1|0|0|-1|nan|nan|nan|nan|nan|0|99.99|4294967295|4294967295|SIN_DATOS|SIN_FILTRO|0|nan|nan|nan|nan|$GPGSA,A,1,,,,,,,,,,,,,99.99,99.99,99.99*30 | X20: =IF(AND(OR($C20="GPRMC",$C20="GNRMC"),OR($D20=1,$D20=TRUE),OR($E20=1,$E20=TRUE),OR($G20=1,$G20=TRUE)),1,0) | Y20: =IF(AND(AND(OR($C20="GPRMC",$C20="GNRMC"),OR($D20=1,$D20=TRUE),OR($E20=1,$E20=TRUE),OR($G20=1,$G20=TRUE)),ISNUMBER($M20)),$M20,"") | Z20: =IF(AND(AND(OR($C20="GPRMC",$C20="GNRMC"),OR($D20=1,$D20=TRUE),OR($E20=1,$E20=TRUE),OR($G20=1,$G20=TRUE)),OR($U20=1,$U20=TRUE),ISNUMBER($M20)),$M20,"")
A21: 2026-10-18T16:15:51.366-07:00 | B21: 383298131 | C21: GPGSV | D21: 1 | E21: 0 | F21: -1 | G21: 0 | H21: 0 | I21: -1 | O21: 0 | P21: 99.99 | Q21: 4294967295 | R21: 4294967295 | S21: SIN_DATOS | T21: SIN_FILTRO | U21: 0 | V21: $GPGSV,1,1,00*79 | W21: I (383563) GPS: GPSDIAG|1|383298131|GPGSV|1|0|-1|0|0|-1|nan|nan|nan|nan|nan|0|99.99|4294967295|4294967295|SIN_DATOS|SIN_FILTRO|0|nan|nan|nan|nan|$GPGSV,1,1,00*79 | X21: =IF(AND(OR($C21="GPRMC",$C21="GNRMC"),OR($D21=1,$D21=TRUE),OR($E21=1,$E21=TRUE),OR($G21=1,$G21=TRUE)),1,0) | Y21: =IF(AND(AND(OR($C21="GPRMC",$C21="GNRMC"),OR($D21=1,$D21=TRUE),OR($E21=1,$E21=TRUE),OR($G21=1,$G21=TRUE)),ISNUMBER($M21)),$M21,"") | Z21: =IF(AND(AND(OR($C21="GPRMC",$C21="GNRMC"),OR($D21=1,$D21=TRUE),OR($E21=1,$E21=TRUE),OR($G21=1,$G21=TRUE)),OR($U21=1,$U21=TRUE),ISNUMBER($M21)),$M21,"")
A22: 2026-10-18T16:15:51.382-07:00 | B22: 383312309 | C22: GPGLL | D22: 1 | E22: 0 | F22: -1 | G22: 0 | H22: 0 | I22: -1 | O22: 0 | P22: 99.99 | Q22: 4294967295 | R22: 4294967295 | S22: SIN_DATOS | T22: SIN_FILTRO | U22: 0 | V22: $GPGLL,,,,,,V,N*64 | W22: I (383583) GPS: GPSDIAG|1|383312309|GPGLL|1|0|-1|0|0|-1|nan|nan|nan|nan|nan|0|99.99|4294967295|4294967295|SIN_DATOS|SIN_FILTRO|0|nan|nan|nan|nan|$GPGLL,,,,,,V,N*64 | X22: =IF(AND(OR($C22="GPRMC",$C22="GNRMC"),OR($D22=1,$D22=TRUE),OR($E22=1,$E22=TRUE),OR($G22=1,$G22=TRUE)),1,0) | Y22: =IF(AND(AND(OR($C22="GPRMC",$C22="GNRMC"),OR($D22=1,$D22=TRUE),OR($E22=1,$E22=TRUE),OR($G22=1,$G22=TRUE)),ISNUMBER($M22)),$M22,"") | Z22: =IF(AND(AND(OR($C22="GPRMC",$C22="GNRMC"),OR($D22=1,$D22=TRUE),OR($E22=1,$E22=TRUE),OR($G22=1,$G22=TRUE)),OR($U22=1,$U22=TRUE),ISNUMBER($M22)),$M22,"")
... A34: 2026-10-18T16:15:53.382-07:00 | B34: 385312229 | C34: GPGLL | D34: 1 | E34: 0 | F34: -1 | G34: 0 | H34: 0 | I34: -1 | O34: 0 | P34: 99.99 | Q34: 4294967295 | R34: 4294967295 | S34: SIN_DATOS | T34: SIN_FILTRO | U34: 0 | V34: $GPGLL,,,,,,V,N*64 | W34: I (385583) GPS: GPSDIAG|1|385312229|GPGLL|1|0|-1|0|0|-1|nan|nan|nan|nan|nan|0|99.99|4294967295|4294967295|SIN_DATOS|SIN_FILTRO|0|nan|nan|nan|nan|$GPGLL,,,,,,V,N*64 | X34: =IF(AND(OR($C34="GPRMC",$C34="GNRMC"),OR($D34=1,$D34=TRUE),OR($E34=1,$E34=TRUE),OR($G34=1,$G34=TRUE)),1,0) | Y34: =IF(AND(AND(OR($C34="GPRMC",$C34="GNRMC"),OR($D34=1,$D34=TRUE),OR($E34=1,$E34=TRUE),OR($G34=1,$G34=TRUE)),ISNUMBER($M34)),$M34,"") | Z34: =IF(AND(AND(OR($C34="GPRMC",$C34="GNRMC"),OR($D34=1,$D34=TRUE),OR($E34=1,$E34=TRUE),OR($G34=1,$G34=TRUE)),OR($U34=1,$U34=TRUE),ISNUMBER($M34)),$M34,"")

Sheet ventana_00_IMU
A1: IMU — prueba_03_ventana_00.xlsx
A3: Muestras IMU | B3: Aceleración lineal | C3: Giroscopio | D3: Cuaterniones | E3: Aceleración media (m/s²) | F3: Giro medio (rad/s) | G3: Norma media cuaternión | H3: Duración IMU (s)
A4: =COUNTA($B$11:$B$127) | B4: =COUNTIF($B$11:$B$127,"LINEAR_ACCEL") | C4: =COUNTIF($B$11:$B$127,"GYRO") | D4: =COUNTIF($B$11:$B$127,"ROTATION_QUAT") | E4: =IFERROR(AVERAGE($L$11:$L$127),"") | F4: =IFERROR(AVERAGE($M$11:$M$127),"") | G4: =IFERROR(AVERAGE($N$11:$N$127),"") | H4: =IFERROR((MAX($D$11:$D$127)-MIN($D$11:$D$127))/1000000,0)
A10: hora_pc | B10: tipo | C10: recibido_esp_us | D10: timestamp_reporte_us | E10: x | F10: y | G10: z | H10: w | I10: estado_sensor | J10: linea_serial | K10: tiempo_desde_inicio_s | L10: magnitud_aceleracion_lineal_m_s2 | M10: magnitud_giroscopio_rad_s | N10: norma_cuaternion
A11: 2026-10-18T16:15:49.958-07:00 | B11: GYRO | C11: 381911329 | D11: 381908172 | E11: 0 | F11: 0 | G11: -0.00195 | I11: 0 | J11: I (382183) IMU: IMU|1|381911329|381908172|GYRO|0.00000|0.00000|-0.00195|0 | K11: =IF(ISNUMBER($D11),($D11-$D$11)/1000000,"") | L11: =IF($B11="LINEAR_ACCEL",SQRT($E11^2+$F11^2+$G11^2),"") | M11: =IF($B11="GYRO",SQRT($E11^2+$F11^2+$G11^2),"") | N11: =IF($B11="ROTATION_QUAT",SQRT($E11^2+$F11^2+$G11^2+$H11^2),"")
A12: 2026-10-18T16:15:49.973-07:00 | B12: ROTATION_QUAT | C12: 381921767 | D12: 381907855 | E12: 0.017456 | F12: -0.042175 | G12: -0.40686 | H12: 0.912354 | I12: 0 | J12: I (382193) IMU: IMU|1|381921767|381907855|ROTATION_QUAT|0.017456|-0.042175|-0.406860|0.912354|0 | K12: =IF(ISNUMBER($D12),($D12-$D$11)/1000000,"") | L12: =IF($B12="LINEAR_ACCEL",SQRT($E12^2+$F12^2+$G12^2),"") | M12: =IF($B12="GYRO",SQRT($E12^2+$F12^2+$G12^2),"") | N12: =IF($B12="ROTATION_QUAT",SQRT($E12^2+$F12^2+$G12^2+$H12^2),"")
A13: 2026-10-18T16:15:49.978-07:00 | B13: LINEAR_ACCEL | C13: 381922334 | D13: 381907855 | E13: 0.00391 | F13: 0.01172 | G13: 0.00391 | I13: 3 | J13: I (382193) IMU: IMU|1|381922334|381907855|LINEAR_ACCEL|0.00391|0.01172|0.00391|3 | K13: =IF(ISNUMBER($D13),($D13-$D$11)/1000000,"") | L13: =IF($B13="LINEAR_ACCEL",SQRT($E13^2+$F13^2+$G13^2),"") | M13: =IF($B13="GYRO",SQRT($E13^2+$F13^2+$G13^2),"") | N13: =IF($B13="ROTATION_QUAT",SQRT($E13^2+$F13^2+$G13^2+$H13^2),"")
A14: 2026-10-18T16:15:50.058-07:00 | B14: GYRO | C14: 382011321 | D14: 382008172 | E14: 0 | F14: 0.00195 | G14: 0 | I14: 0 | J14: I (382283) IMU: IMU|1|382011321|382008172|GYRO|0.00000|0.00195|0.00000|0 | K14: =IF(ISNUMBER($D14),($D14-$D$11)/1000000,"") | L14: =IF($B14="LINEAR_ACCEL",SQRT($E14^2+$F14^2+$G14^2),"") | M14: =IF($B14="GYRO",SQRT($E14^2+$F14^2+$G14^2),"") | N14: =IF($B14="ROTATION_QUAT",SQRT($E14^2+$F14^2+$G14^2+$H14^2),"")
A15: 2026-10-18T16:15:50.073-07:00 | B15: ROTATION_QUAT | C15: 382021768 | D15: 382008155 | E15: 0.017517 | F15: -0.042175 | G15: -0.40686 | H15: 0.912354 | I15: 0 | J15: I (382293) IMU: IMU|1|382021768|382008155|ROTATION_QUAT|0.017517|-0.042175|-0.406860|0.912354|0 | K15: =IF(ISNUMBER($D15),($D15-$D$11)/1000000,"") | L15: =IF($B15="LINEAR_ACCEL",SQRT($E15^2+$F15^2+$G15^2),"") | M15: =IF($B15="GYRO",SQRT($E15^2+$F15^2+$G15^2),"") | N15: =IF($B15="ROTATION_QUAT",SQRT($E15^2+$F15^2+$G15^2+$H15^2),"")
A16: 2026-10-18T16:15:50.078-07:00 | B16: LINEAR_ACCEL | C16: 382022335 | D16: 382008155 | E16: 0.00391 | F16: 0.00391 | G16: 0.00391 | I16: 3 | J16: I (382293) IMU: IMU|1|382022335|382008155|LINEAR_ACCEL|0.00391|0.00391|0.00391|3 | K16: =IF(ISNUMBER($D16),($D16-$D$11)/1000000,"") | L16: =IF($B16="LINEAR_ACCEL",SQRT($E16^2+$F16^2+$G16^2),"") | M16: =IF($B16="GYRO",SQRT($E16^2+$F16^2+$G16^2),"") | N16: =IF($B16="ROTATION_QUAT",SQRT($E16^2+$F16^2+$G16^2+$H16^2),"")
A17: 2026-10-18T16:15:50.158-07:00 | B17: GYRO | C17: 382111315 | D17: 382108172 | E17: 0 | F17: 0 | G17: 0 | I17: 0 | J17: I (382383) IMU: IMU|1|382111315|382108172|GYRO|0.00000|0.00000|0.00000|0 | K17: =IF(ISNUMBER($D17),($D17-$D$11)/1000000,"") | L17: =IF($B17="LINEAR_ACCEL",SQRT($E17^2+$F17^2+$G17^2),"") | M17: =IF($B17="GYRO",SQRT($E17^2+$F17^2+$G17^2),"") | N17: =IF($B17="ROTATION_QUAT",SQRT($E17^2+$F17^2+$G17^2+$H17^2),"")
A18: 2026-10-18T16:15:50.173-07:00 | B18: ROTATION_QUAT | C18: 382121719 | D18: 382108131 | E18: 0.017578 | F18: -0.042236 | G18: -0.406799 | H18: 0.912354 | I18: 0 | J18: I (382393) IMU: IMU|1|382121719|382108131|ROTATION_QUAT|0.017578|-0.042236|-0.406799|0.912354|0 | K18: =IF(ISNUMBER($D18),($D18-$D$11)/1000000,"") | L18: =IF($B18="LINEAR_ACCEL",SQRT($E18^2+$F18^2+$G18^2),"") | M18: =IF($B18="GYRO",SQRT($E18^2+$F18^2+$G18^2),"") | N18: =IF($B18="ROTATION_QUAT",SQRT($E18^2+$F18^2+$G18^2+$H18^2),"")
A19: 2026-10-18T16:15:50.178-07:00 | B19: LINEAR_ACCEL | C19: 382122294 | D19: 382108131 | E19: 0.00391 | F19: -0.00391 | G19: 0.00391 | I19: 3 | J19: I (382393) IMU: IMU|1|382122294|382108131|LINEAR_ACCEL|0.00391|-0.00391|0.00391|3 | K19: =IF(ISNUMBER($D19),($D19-$D$11)/1000000,"") | L19: =IF($B19="LINEAR_ACCEL",SQRT($E19^2+$F19^2+$G19^2),"") | M19: =IF($B19="GYRO",SQRT($E19^2+$F19^2+$G19^2),"") | N19: =IF($B19="ROTATION_QUAT",SQRT($E19^2+$F19^2+$G19^2+$H19^2),"")
A20: 2026-10-18T16:15:50.258-07:00 | B20: GYRO | C20: 382211312 | D20: 382207772 | E20: 0.00195 | F20: -0.00195 | G20: 0 | I20: 0 | J20: I (382483) IMU: IMU|1|382211312|382207772|GYRO|0.00195|-0.00195|0.00000|0 | K20: =IF(ISNUMBER($D20),($D20-$D$11)/1000000,"") | L20: =IF($B20="LINEAR_ACCEL",SQRT($E20^2+$F20^2+$G20^2),"") | M20: =IF($B20="GYRO",SQRT($E20^2+$F20^2+$G20^2),"") | N20: =IF($B20="ROTATION_QUAT",SQRT($E20^2+$F20^2+$G20^2+$H20^2),"")
A21: 2026-10-18T16:15:50.273-07:00 | B21: ROTATION_QUAT | C21: 382221764 | D21: 382208055 | E21: 0.0177 | F21: -0.042297 | G21: -0.406799 | H21: 0.912354 | I21: 0 | J21: I (382493) IMU: IMU|1|382221764|382208055|ROTATION_QUAT|0.017700|-0.042297|-0.406799|0.912354|0 | K21: =IF(ISNUMBER($D21),($D21-$D$11)/1000000,"") | L21: =IF($B21="LINEAR_ACCEL",SQRT($E21^2+$F21^2+$G21^2),"") | M21: =IF($B21="GYRO",SQRT($E21^2+$F21^2+$G21^2),"") | N21: =IF($B21="ROTATION_QUAT",SQRT($E21^2+$F21^2+$G21^2+$H21^2),"")
A22: 2026-10-18T16:15:50.278-07:00 | B22: LINEAR_ACCEL | C22: 382222339 | D22: 382208055 | E22: 0.00391 | F22: -0.00391 | G22: -0.00391 | I22: 3 | J22: I (382493) IMU: IMU|1|382222339|382208055|LINEAR_ACCEL|0.00391|-0.00391|-0.00391|3 | K22: =IF(ISNUMBER($D22),($D22-$D$11)/1000000,"") | L22: =IF($B22="LINEAR_ACCEL",SQRT($E22^2+$F22^2+$G22^2),"") | M22: =IF($B22="GYRO",SQRT($E22^2+$F22^2+$G22^2),"") | N22: =IF($B22="ROTATION_QUAT",SQRT($E22^2+$F22^2+$G22^2+$H22^2),"")
A23: 2026-10-18T16:15:50.388-07:00 | B23: GYRO | C23: 382327929 | D23: 382308183 | E23: -0.00195 | F23: 0 | G23: 0 | I23: 0 | J23: I (382593) IMU: IMU|1|382327929|382308183|GYRO|-0.00195|0.00000|0.00000|0 | K23: =IF(ISNUMBER($D23),($D23-$D$11)/1000000,"") | L23: =IF($B23="LINEAR_ACCEL",SQRT($E23^2+$F23^2+$G23^2),"") | M23: =IF($B23="GYRO",SQRT($E23^2+$F23^2+$G23^2),"") | N23: =IF($B23="ROTATION_QUAT",SQRT($E23^2+$F23^2+$G23^2+$H23^2),"")
A24: 2026-10-18T16:15:50.394-07:00 | B24: ROTATION_QUAT | C24: 382341796 | D24: 382311671 | E24: 0.017761 | F24: -0.042297 | G24: -0.406799 | H24: 0.912354 | I24: 0 | J24: I (382613) IMU: IMU|1|382341796|382311671|ROTATION_QUAT|0.017761|-0.042297|-0.406799|0.912354|0 | K24: =IF(ISNUMBER($D24),($D24-$D$11)/1000000,"") | L24: =IF($B24="LINEAR_ACCEL",SQRT($E24^2+$F24^2+$G24^2),"") | M24: =IF($B24="GYRO",SQRT($E24^2+$F24^2+$G24^2),"") | N24: =IF($B24="ROTATION_QUAT",SQRT($E24^2+$F24^2+$G24^2+$H24^2),"")
A25: 2026-10-18T16:15:50.399-07:00 | B25: LINEAR_ACCEL | C25: 382342387 | D25: 382311671 | E25: 0.00391 | F25: -0.00391 | G25: -0.04297 | I25: 3 | J25: I (382613) IMU: IMU|1|382342387|382311671|LINEAR_ACCEL|0.00391|-0.00391|-0.04297|3 | K25: =IF(ISNUMBER($D25),($D25-$D$11)/1000000,"") | L25: =IF($B25="LINEAR_ACCEL",SQRT($E25^2+$F25^2+$G25^2),"") | M25: =IF($B25="GYRO",SQRT($E25^2+$F25^2+$G25^2),"") | N25: =IF($B25="ROTATION_QUAT",SQRT($E25^2+$F25^2+$G25^2+$H25^2),"")
A26: 2026-10-18T16:15:50.458-07:00 | B26: GYRO | C26: 382411311 | D26: 382408172 | E26: 0 | F26: -0.00195 | G26: 0 | I26: 0 | J26: I (382683) IMU: IMU|1|382411311|382408172|GYRO|0.00000|-0.00195|0.00000|0 | K26: =IF(ISNUMBER($D26),($D26-$D$11)/1000000,"") | L26: =IF($B26="LINEAR_ACCEL",SQRT($E26^2+$F26^2+$G26^2),"") | M26: =IF($B26="GYRO",SQRT($E26^2+$F26^2+$G26^2),"") | N26: =IF($B26="ROTATION_QUAT",SQRT($E26^2+$F26^2+$G26^2+$H26^2),"")
A27: 2026-10-18T16:15:50.473-07:00 | B27: ROTATION_QUAT | C27: 382421763 | D27: 382407955 | E27: 0.017761 | F27: -0.042297 | G27: -0.406799 | H27: 0.912354 | I27: 0 | J27: I (382693) IMU: IMU|1|382421763|382407955|ROTATION_QUAT|0.017761|-0.042297|-0.406799|0.912354|0 | K27: =IF(ISNUMBER($D27),($D27-$D$11)/1000000,"") | L27: =IF($B27="LINEAR_ACCEL",SQRT($E27^2+$F27^2+$G27^2),"") | M27: =IF($B27="GYRO",SQRT($E27^2+$F27^2+$G27^2),"") | N27: =IF($B27="ROTATION_QUAT",SQRT($E27^2+$F27^2+$G27^2+$H27^2),"")
A28: 2026-10-18T16:15:50.478-07:00 | B28: LINEAR_ACCEL | C28: 382422323 | D28: 382407955 | E28: 0.00391 | F28: -0.00391 | G28: 0.00391 | I28: 3 | J28: I (382693) IMU: IMU|1|382422323|382407955|LINEAR_ACCEL|0.00391|-0.00391|0.00391|3 | K28: =IF(ISNUMBER($D28),($D28-$D$11)/1000000,"") | L28: =IF($B28="LINEAR_ACCEL",SQRT($E28^2+$F28^2+$G28^2),"") | M28: =IF($B28="GYRO",SQRT($E28^2+$F28^2+$G28^2),"") | N28: =IF($B28="ROTATION_QUAT",SQRT($E28^2+$F28^2+$G28^2+$H28^2),"")
A29: 2026-10-18T16:15:50.558-07:00 | B29: GYRO | C29: 382511318 | D29: 382508172 | E29: -0.00586 | F29: 0.00195 | G29: -0.00195 | I29: 0 | J29: I (382783) IMU: IMU|1|382511318|382508172|GYRO|-0.00586|0.00195|-0.00195|0 | K29: =IF(ISNUMBER($D29),($D29-$D$11)/1000000,"") | L29: =IF($B29="LINEAR_ACCEL",SQRT($E29^2+$F29^2+$G29^2),"") | M29: =IF($B29="GYRO",SQRT($E29^2+$F29^2+$G29^2),"") | N29: =IF($B29="ROTATION_QUAT",SQRT($E29^2+$F29^2+$G29^2+$H29^2),"")
A30: 2026-10-18T16:15:50.573-07:00 | B30: ROTATION_QUAT | C30: 382521743 | D30: 382508143 | E30: 0.017822 | F30: -0.042297 | G30: -0.406799 | H30: 0.912354 | I30: 0 | J30: I (382793) IMU: IMU|1|382521743|382508143|ROTATION_QUAT|0.017822|-0.042297|-0.406799|0.912354|0 | K30: =IF(ISNUMBER($D30),($D30-$D$11)/1000000,"") | L30: =IF($B30="LINEAR_ACCEL",SQRT($E30^2+$F30^2+$G30^2),"") | M30: =IF($B30="GYRO",SQRT($E30^2+$F30^2+$G30^2),"") | N30: =IF($B30="ROTATION_QUAT",SQRT($E30^2+$F30^2+$G30^2+$H30^2),"")
A31: 2026-10-18T16:15:50.578-07:00 | B31: LINEAR_ACCEL | C31: 382522303 | D31: 382508143 | E31: 0.00391 | F31: -0.00391 | G31: 0.00391 | I31: 3 | J31: I (382793) IMU: IMU|1|382522303|382508143|LINEAR_ACCEL|0.00391|-0.00391|0.00391|3 | K31: =IF(ISNUMBER($D31),($D31-$D$11)/1000000,"") | L31: =IF($B31="LINEAR_ACCEL",SQRT($E31^2+$F31^2+$G31^2),"") | M31: =IF($B31="GYRO",SQRT($E31^2+$F31^2+$G31^2),"") | N31: =IF($B31="ROTATION_QUAT",SQRT($E31^2+$F31^2+$G31^2+$H31^2),"")
A32: 2026-10-18T16:15:50.658-07:00 | B32: GYRO | C32: 382611310 | D32: 382608172 | E32: -0.00195 | F32: 0 | G32: 0 | I32: 0 | J32: I (382883) IMU: IMU|1|382611310|382608172|GYRO|-0.00195|0.00000|0.00000|0 | K32: =IF(ISNUMBER($D32),($D32-$D$11)/1000000,"") | L32: =IF($B32="LINEAR_ACCEL",SQRT($E32^2+$F32^2+$G32^2),"") | M32: =IF($B32="GYRO",SQRT($E32^2+$F32^2+$G32^2),"") | N32: =IF($B32="ROTATION_QUAT",SQRT($E32^2+$F32^2+$G32^2+$H32^2),"")
A33: 2026-10-18T16:15:50.673-07:00 | B33: ROTATION_QUAT | C33: 382621764 | D33: 382608255 | E33: 0.017822 | F33: -0.042358 | G33: -0.406799 | H33: 0.912354 | I33: 0 | J33: I (382893) IMU: IMU|1|382621764|382608255|ROTATION_QUAT|0.017822|-0.042358|-0.406799|0.912354|0 | K33: =IF(ISNUMBER($D33),($D33-$D$11)/1000000,"") | L33: =IF($B33="LINEAR_ACCEL",SQRT($E33^2+$F33^2+$G33^2),"") | M33: =IF($B33="GYRO",SQRT($E33^2+$F33^2+$G33^2),"") | N33: =IF($B33="ROTATION_QUAT",SQRT($E33^2+$F33^2+$G33^2+$H33^2),"")
A34: 2026-10-18T16:15:50.678-07:00 | B34: LINEAR_ACCEL | C34: 382622331 | D34: 382608255 | E34: 0.00391 | F34: -0.00391 | G34: 0.00391 | I34: 3 | J34: I (382893) IMU: IMU|1|382622331|382608255|LINEAR_ACCEL|0.00391|-0.00391|0.00391|3 | K34: =IF(ISNUMBER($D34),($D34-$D$11)/1000000,"") | L34: =IF($B34="LINEAR_ACCEL",SQRT($E34^2+$F34^2+$G34^2),"") | M34: =IF($B34="GYRO",SQRT($E34^2+$F34^2+$G34^2),"") | N34: =IF($B34="ROTATION_QUAT",SQRT($E34^2+$F34^2+$G34^2+$H34^2),"")
A35: 2026-10-18T16:15:50.759-07:00 | B35: GYRO | C35: 382711312 | D35: 382707572 | E35: 0.00195 | F35: 0 | G35: 0 | I35: 0 | J35: I (382983) IMU: IMU|1|382711312|382707572|GYRO|0.00195|0.00000|0.00000|0 | K35: =IF(ISNUMBER($D35),($D35-$D$11)/1000000,"") | L35: =IF($B35="LINEAR_ACCEL",SQRT($E35^2+$F35^2+$G35^2),"") | M35: =IF($B35="GYRO",SQRT($E35^2+$F35^2+$G35^2),"") | N35: =IF($B35="ROTATION_QUAT",SQRT($E35^2+$F35^2+$G35^2+$H35^2),"")
A36: 2026-10-18T16:15:50.773-07:00 | B36: ROTATION_QUAT | C36: 382721761 | D36: 382708155 | E36: 0.017883 | F36: -0.042297 | G36: -0.406799 | H36: 0.912354 | I36: 0 | J36: I (382993) IMU: IMU|1|382721761|382708155|ROTATION_QUAT|0.017883|-0.042297|-0.406799|0.912354|0 | K36: =IF(ISNUMBER($D36),($D36-$D$11)/1000000,"") | L36: =IF($B36="LINEAR_ACCEL",SQRT($E36^2+$F36^2+$G36^2),"") | M36: =IF($B36="GYRO",SQRT($E36^2+$F36^2+$G36^2),"") | N36: =IF($B36="ROTATION_QUAT",SQRT($E36^2+$F36^2+$G36^2+$H36^2),"")
A37: 2026-10-18T16:15:50.778-07:00 | B37: LINEAR_ACCEL | C37: 382722328 | D37: 382708155 | E37: 0.00391 | F37: -0.00391 | G37: -0.00391 | I37: 3 | J37: I (382993) IMU: IMU|1|382722328|382708155|LINEAR_ACCEL|0.00391|-0.00391|-0.00391|3 | K37: =IF(ISNUMBER($D37),($D37-$D$11)/1000000,"") | L37: =IF($B37="LINEAR_ACCEL",SQRT($E37^2+$F37^2+$G37^2),"") | M37: =IF($B37="GYRO",SQRT($E37^2+$F37^2+$G37^2),"") | N37: =IF($B37="ROTATION_QUAT",SQRT($E37^2+$F37^2+$G37^2+$H37^2),"")
A38: 2026-10-18T16:15:50.858-07:00 | B38: GYRO | C38: 382811316 | D38: 382808172 | E38: -0.00195 | F38: 0 | G38: 0 | I38: 0 | J38: I (383083) IMU: IMU|1|382811316|382808172|GYRO|-0.00195|0.00000|0.00000|0 | K38: =IF(ISNUMBER($D38),($D38-$D$11)/1000000,"") | L38: =IF($B38="LINEAR_ACCEL",SQRT($E38^2+$F38^2+$G38^2),"") | M38: =IF($B38="GYRO",SQRT($E38^2+$F38^2+$G38^2),"") | N38: =IF($B38="ROTATION_QUAT",SQRT($E38^2+$F38^2+$G38^2+$H38^2),"")
A39: 2026-10-18T16:15:50.873-07:00 | B39: ROTATION_QUAT | C39: 382821763 | D39: 382808255 | E39: 0.017944 | F39: -0.042297 | G39: -0.406799 | H39: 0.912354 | I39: 0 | J39: I (383093) IMU: IMU|1|382821763|382808255|ROTATION_QUAT|0.017944|-0.042297|-0.406799|0.912354|0 | K39: =IF(ISNUMBER($D39),($D39-$D$11)/1000000,"") | L39: =IF($B39="LINEAR_ACCEL",SQRT($E39^2+$F39^2+$G39^2),"") | M39: =IF($B39="GYRO",SQRT($E39^2+$F39^2+$G39^2),"") | N39: =IF($B39="ROTATION_QUAT",SQRT($E39^2+$F39^2+$G39^2+$H39^2),"")
A40: 2026-10-18T16:15:50.878-07:00 | B40: LINEAR_ACCEL | C40: 382822331 | D40: 382808255 | E40: 0.00391 | F40: -0.00391 | G40: -0.00391 | I40: 3 | J40: I (383093) IMU: IMU|1|382822331|382808255|LINEAR_ACCEL|0.00391|-0.00391|-0.00391|3 | K40: =IF(ISNUMBER($D40),($D40-$D$11)/1000000,"") | L40: =IF($B40="LINEAR_ACCEL",SQRT($E40^2+$F40^2+$G40^2),"") | M40: =IF($B40="GYRO",SQRT($E40^2+$F40^2+$G40^2),"") | N40: =IF($B40="ROTATION_QUAT",SQRT($E40^2+$F40^2+$G40^2+$H40^2),"")
A41: 2026-10-18T16:15:50.958-07:00 | B41: GYRO | C41: 382911307 | D41: 382908172 | E41: 0 | F41: -0.00195 | G41: 0 | I41: 0 | J41: I (383183) IMU: IMU|1|382911307|382908172|GYRO|0.00000|-0.00195|0.00000|0 | K41: =IF(ISNUMBER($D41),($D41-$D$11)/1000000,"") | L41: =IF($B41="LINEAR_ACCEL",SQRT($E41^2+$F41^2+$G41^2),"") | M41: =IF($B41="GYRO",SQRT($E41^2+$F41^2+$G41^2),"") | N41: =IF($B41="ROTATION_QUAT",SQRT($E41^2+$F41^2+$G41^2+$H41^2),"")
A42: 2026-10-18T16:15:50.973-07:00 | B42: ROTATION_QUAT | C42: 382921762 | D42: 382908255 | E42: 0.017883 | F42: -0.042297 | G42: -0.406799 | H42: 0.912354 | I42: 0 | J42: I (383193) IMU: IMU|1|382921762|382908255|ROTATION_QUAT|0.017883|-0.042297|-0.406799|0.912354|0 | K42: =IF(ISNUMBER($D42),($D42-$D$11)/1000000,"") | L42: =IF($B42="LINEAR_ACCEL",SQRT($E42^2+$F42^2+$G42^2),"") | M42: =IF($B42="GYRO",SQRT($E42^2+$F42^2+$G42^2),"") | N42: =IF($B42="ROTATION_QUAT",SQRT($E42^2+$F42^2+$G42^2+$H42^2),"")
A43: 2026-10-18T16:15:50.978-07:00 | B43: LINEAR_ACCEL | C43: 382922321 | D43: 382908255 | E43: 0.00391 | F43: 0.00391 | G43: -0.00391 | I43: 3 | J43: I (383193) IMU: IMU|1|382922321|382908255|LINEAR_ACCEL|0.00391|0.00391|-0.00391|3 | K43: =IF(ISNUMBER($D43),($D43-$D$11)/1000000,"") | L43: =IF($B43="LINEAR_ACCEL",SQRT($E43^2+$F43^2+$G43^2),"") | M43: =IF($B43="GYRO",SQRT($E43^2+$F43^2+$G43^2),"") | N43: =IF($B43="ROTATION_QUAT",SQRT($E43^2+$F43^2+$G43^2+$H43^2),"")
A44: 2026-10-18T16:15:51.058-07:00 | B44: GYRO | C44: 383011324 | D44: 383008172 | E44: -0.00195 | F44: -0.00195 | G44: 0 | I44: 0 | J44: I (383283) IMU: IMU|1|383011324|383008172|GYRO|-0.00195|-0.00195|0.00000|0 | K44: =IF(ISNUMBER($D44),($D44-$D$11)/1000000,"") | L44: =IF($B44="LINEAR_ACCEL",SQRT($E44^2+$F44^2+$G44^2),"") | M44: =IF($B44="GYRO",SQRT($E44^2+$F44^2+$G44^2),"") | N44: =IF($B44="ROTATION_QUAT",SQRT($E44^2+$F44^2+$G44^2+$H44^2),"")
A45: 2026-10-18T16:15:51.073-07:00 | B45: ROTATION_QUAT | C45: 383021752 | D45: 383008255 | E45: 0.017883 | F45: -0.042297 | G45: -0.406799 | H45: 0.912354 | I45: 0 | J45: I (383293) IMU: IMU|1|383021752|383008255|ROTATION_QUAT|0.017883|-0.042297|-0.406799|0.912354|0 | K45: =IF(ISNUMBER($D45),($D45-$D$11)/1000000,"") | L45: =IF($B45="LINEAR_ACCEL",SQRT($E45^2+$F45^2+$G45^2),"") | M45: =IF($B45="GYRO",SQRT($E45^2+$F45^2+$G45^2),"") | N45: =IF($B45="ROTATION_QUAT",SQRT($E45^2+$F45^2+$G45^2+$H45^2),"")
A46: 2026-10-18T16:15:51.078-07:00 | B46: LINEAR_ACCEL | C46: 383022319 | D46: 383008255 | E46: 0.00391 | F46: -0.00391 | G46: -0.00391 | I46: 3 | J46: I (383293) IMU: IMU|1|383022319|383008255|LINEAR_ACCEL|0.00391|-0.00391|-0.00391|3 | K46: =IF(ISNUMBER($D46),($D46-$D$11)/1000000,"") | L46: =IF($B46="LINEAR_ACCEL",SQRT($E46^2+$F46^2+$G46^2),"") | M46: =IF($B46="GYRO",SQRT($E46^2+$F46^2+$G46^2),"") | N46: =IF($B46="ROTATION_QUAT",SQRT($E46^2+$F46^2+$G46^2+$H46^2),"")
...

Sheet ventana_00_Eventos
A1: Eventos — prueba_03_ventana_00.xlsx
A3: Registros de evento | B3: =0
A10: hora_pc | B10: linea_serial
